[09/May/2025 13:07:23] "POST /EISHome/portwise_top5_FiveM/SYS/ HTTP/1.0" 500 131344
Internal Server Error: /PyPortal/EISHome/servicewise_top5_FiveM/SYS/
Traceback (most recent call last):
  File "/var/www/cgi-bin/PyPortal/EISHome/views.py", line 300, in serviceWiseTime
    return JsonResponse({"403 Bad Request"},status=403,safe=False)
  File "/var/www/cgi-bin/djangovenv/venv/lib64/python3.9/site-packages/Django-4.2.16-py3.9.egg/django/http/response.py", line 731, in __init__
    data = json.dumps(data, cls=encoder, **json_dumps_params)
  File "/usr/lib64/python3.9/json/__init__.py", line 234, in dumps
    return cls(
  File "/usr/lib64/python3.9/json/encoder.py", line 199, in encode
    chunks = self.iterencode(o, _one_shot=True)
  File "/usr/lib64/python3.9/json/encoder.py", line 257, in iterencode
    return _iterencode(o, 0)
  File "/var/www/cgi-bin/djangovenv/venv/lib64/python3.9/site-packages/Django-4.2.16-py3.9.egg/django/core/serializers/json.py", line 106, in default
    return super().default(o)
  File "/usr/lib64/python3.9/json/encoder.py", line 179, in default
    raise TypeError(f'Object of type {o.__class__.__name__} '
TypeError: Object of type set is not JSON serializable

During handling of the above exception, another exception occurred:

Traceback (most recent call last):
  File "/var/www/cgi-bin/djangovenv/venv/lib64/python3.9/site-packages/Django-4.2.16-py3.9.egg/django/core/handlers/exception.py", line 55, in inner
    response = get_response(request)
  File "/var/www/cgi-bin/djangovenv/venv/lib64/python3.9/site-packages/Django-4.2.16-py3.9.egg/django/core/handlers/base.py", line 197, in _get_response
    response = wrapped_callback(request, *callback_args, **callback_kwargs)
  File "/var/www/cgi-bin/djangovenv/venv/lib64/python3.9/site-packages/Django-4.2.16-py3.9.egg/django/views/decorators/csrf.py", line 56, in wrapper_view
    return view_func(*args, **kwargs)
  File "/var/www/cgi-bin/PyPortal/EISHome/views.py", line 310, in serviceWiseTime
    return JsonResponse({"An error occured while fetching the data"},status=500,safe=False)
  File "/var/www/cgi-bin/djangovenv/venv/lib64/python3.9/site-packages/Django-4.2.16-py3.9.egg/django/http/response.py", line 731, in __init__
    data = json.dumps(data, cls=encoder, **json_dumps_params)
  File "/usr/lib64/python3.9/json/__init__.py", line 234, in dumps
    return cls(
  File "/usr/lib64/python3.9/json/encoder.py", line 199, in encode
    chunks = self.iterencode(o, _one_shot=True)
  File "/usr/lib64/python3.9/json/encoder.py", line 257, in iterencode
    return _iterencode(o, 0)
  File "/var/www/cgi-bin/djangovenv/venv/lib64/python3.9/site-packages/Django-4.2.16-py3.9.egg/django/core/serializers/json.py", line 106, in default
    return super().default(o)
  File "/usr/lib64/python3.9/json/encoder.py", line 179, in default
    raise TypeError(f'Object of type {o.__class__.__name__} '
TypeError: Object of type set is not JSON serializable


[09/May/2025 13:07:23] "POST /EISHome/servicewise_top5_FiveM/SYS/ HTTP/1.0" 500 131404
Internal Server Error: /PyPortal/EISHome/servicewise_top5_FiveM/EXP/
Traceback (most recent call last):
  File "/var/www/cgi-bin/PyPortal/EISHome/views.py", line 300, in serviceWiseTime
    return JsonResponse({"403 Bad Request"},status=403,safe=False)
  File "/var/www/cgi-bin/djangovenv/venv/lib64/python3.9/site-packages/Django-4.2.16-py3.9.egg/django/http/response.py", line 731, in __init__
    data = json.dumps(data, cls=encoder, **json_dumps_params)
  File "/usr/lib64/python3.9/json/__init__.py", line 234, in dumps
    return cls(
  File "/usr/lib64/python3.9/json/encoder.py", line 199, in encode
    chunks = self.iterencode(o, _one_shot=True)
  File "/usr/lib64/python3.9/json/encoder.py", line 257, in iterencode
    return _iterencode(o, 0)
  File "/var/www/cgi-bin/djangovenv/venv/lib64/python3.9/site-packages/Django-4.2.16-py3.9.egg/django/core/serializers/json.py", line 106, in default
    return super().default(o)
  File "/usr/lib64/python3.9/json/encoder.py", line 179, in default
    raise TypeError(f'Object of type {o.__class__.__name__} '
TypeError: Object of type set is not JSON serializable

During handling of the above exception, another exception occurred:

Traceback (most recent call last):
  File "/var/www/cgi-bin/djangovenv/venv/lib64/python3.9/site-packages/Django-4.2.16-py3.9.egg/django/core/handlers/exception.py", line 55, in inner
    response = get_response(request)
  File "/var/www/cgi-bin/djangovenv/venv/lib64/python3.9/site-packages/Django-4.2.16-py3.9.egg/django/core/handlers/base.py", line 197, in _get_response
    response = wrapped_callback(request, *callback_args, **callback_kwargs)
  File "/var/www/cgi-bin/djangovenv/venv/lib64/python3.9/site-packages/Django-4.2.16-py3.9.egg/django/views/decorators/csrf.py", line 56, in wrapper_view
    return view_func(*args, **kwargs)
  File "/var/www/cgi-bin/PyPortal/EISHome/views.py", line 310, in serviceWiseTime
    return JsonResponse({"An error occured while fetching the data"},status=500,safe=False)
  File "/var/www/cgi-bin/djangovenv/venv/lib64/python3.9/site-packages/Django-4.2.16-py3.9.egg/django/http/response.py", line 731, in __init__
    data = json.dumps(data, cls=encoder, **json_dumps_params)
  File "/usr/lib64/python3.9/json/__init__.py", line 234, in dumps
    return cls(
  File "/usr/lib64/python3.9/json/encoder.py", line 199, in encode
    chunks = self.iterencode(o, _one_shot=True)
  File "/usr/lib64/python3.9/json/encoder.py", line 257, in iterencode
    return _iterencode(o, 0)
  File "/var/www/cgi-bin/djangovenv/venv/lib64/python3.9/site-packages/Django-4.2.16-py3.9.egg/django/core/serializers/json.py", line 106, in default
    return super().default(o)
  File "/usr/lib64/python3.9/json/encoder.py", line 179, in default
    raise TypeError(f'Object of type {o.__class__.__name__} '
TypeError: Object of type set is not JSON serializable
